Workbook
Name _ftn1: '7A'!$A$23
Name _ftnref1: '7A'!#REF!

Sheet Data Input
B1: Current Year | H1: 2022
B2: No of Year Audited | H2: 5
B3: No of Year Projected (Excl. current year) | H3: 2
A4: Name of Party | B4: H R Ispat Pvt Ltd
A5: Name of Bank | B5: Punjab National Bank
A6: Name of Branch | B6: MCC Durgapur
A7: Name of CO | B7: Durgapur
C8: 5 | D8: 4 | E8: 3 | F8: 2 | G8: 1 | H8: 0 | I8: 1 | J8: 2 | K8: 3 | L8: 3
C9: =+IF($H$2<C8,0,1) -> 1 | D9: =+IF($H$2<D8,0,1) -> 1 | E9: =+IF($H$2<E8,0,1) -> 1 | F9: =+IF($H$2<F8,0,1) -> 1 | G9: =+IF($H$2<G8,0,1) -> 1 | H9: 1 | I9: =+IF(I8<=$H$3, 1, 0) -> 1 | J9: =+IF(J8<=$H$3, 1, 0) -> 1 | K9: =+IF(K8<=$H$3, 1, 0) -> 0 | L9: =+IF(L8<=$H$3, 1, 0) -> 0
C10: Audited | D10: Audited | E10: Audited | F10: Audited | G10: Audited | H10: Audited | I10: Audited | J10: Audited | K10: Projected | L10: Projected
B11: YEAR ENDING 31ST MARCH | C11: =IF(D11="", "", D11-1) -> 2017 | D11: =IF(E11="", "", E11-1) -> 2018 | E11: =IF(F11="", "", F11-1) -> 2019 | F11: =IF(G11="", "", G11-1) -> 2020 | G11: =IF(H11="", "", H11-1) -> 2021 | H11: =+IF(H1="", "", H1) -> 2022 | I11: =IF(H11="", "", H11+1) -> 2023 | J11: =IF(I11="", "", I11+1) -> 2024 | K11: =IF(J11="", "", J11+1) -> 2025 | L11: =IF(K11="", "", K11+1) -> 2026
B12: GROSS SALES | C12: =SUM(C13:C14) -> 0 | D12: =SUM(D13:D14) -> 0 | E12: =SUM(E13:E14) -> 0 | F12: =SUM(F13:F14) -> 0 | G12: =SUM(G13:G14) -> 0 | H12: =SUM(H13:H14) -> 0 | I12: =SUM(I13:I14) -> 564.38 | J12: =SUM(J13:J14) -> 471.12 | ... L12: =SUM(L13:L14) -> 603.94
B13: Domestic Sales | I13: 564.38 | J13: 471.12 | K13: 528.88 | L13: 603.94
B14: Exports Sales
B15: Other Operating INCOME
B16: TOTAL | C16: =SUM(C13:C15) -> 0 | D16: =SUM(D13:D15) -> 0 | E16: =SUM(E13:E15) -> 0 | F16: =SUM(F13:F15) -> 0 | G16: =SUM(G13:G15) -> 0 | H16: =SUM(H13:H15) -> 0 | I16: =SUM(I13:I15) -> 564.38 | J16: =SUM(J13:J15) -> 471.12 | ... L16: =SUM(L13:L15) -> 603.94
B17: Less: Excise Duty / taxes
B18: NET SALES | C18: =C16-C17 -> 0 | D18: =D16-D17 -> 0 | E18: =E16-E17 -> 0 | F18: =F16-F17 -> 0 | G18: =G16-G17 -> 0 | H18: =H16-H17 -> 0 | I18: =I16-I17 -> 564.38 | J18: =J16-J17 -> 471.12 | ... L18: =L16-L17 -> 603.94
B19: % rise/fall in Net Sales compared to Previous Year | C19: - | D19: =(D18-C18)/C18 -> #DIV/0! | E19: =(E18-D18)/D18 -> #DIV/0! | F19: =(F18-E18)/E18 -> #DIV/0! | G19: =(G18-F18)/F18 -> #DIV/0! | H19: =(H18-G18)/G18 -> #DIV/0! | I19: =(I18-H18)/H18 -> #DIV/0! | J19: =(J18-I18)/I18 -> -0.16524328 | K19: =(K18-J18)/J18 -> 0.12260146 | L19: =(L18-K18)/K18 -> 0.14192255
B20: COST OF SALES
B21: Raw Materials consumption | C21: =IF((C22+C23)="", "", C22+C23) -> 0 | D21: =IF((D22+D23)="", "", D22+D23) -> 0 | E21: =IF((E22+E23)="", "", E22+E23) -> 0 | F21: =IF((F22+F23)="", "", F22+F23) -> 0 | G21: =IF((G22+G23)="", "", G22+G23) -> 0 | H21: =IF((H22+H23)="", "", H22+H23) -> 0 | I21: =IF((I22+I23)="", "", I22+I23) -> 473.14 | J21: =IF((J22+J23)="", "", J22+J23) -> 384.37 | ... L21: =IF((L22+L23)="", "", L22+L23) -> 491.28
B22: a) Import
B23: b) Indigenous | I23: 473.14 | J23: 384.37 | K23: 435.88 | L23: 491.28
B24: Other Spares/packing Material / trading goods | I24: 11.37 | J24: 8.3 | K24: 9.81 | L24: 11.05
B25: Indigenous packing material (Incl. Stores)
B26: Power & Fuel | I26: 71.29 | J26: 61.98 | K26: 70.35 | L26: 80
B27: Direct Cost | I27: 0.8 | J27: 0.89 | K27: 1.63 | L27: 1.79
B28: Other Mfg. Expenses | I28: =0.03+1.17 -> 1.2 | J28: =0.05+0.98 -> 1.03 | K28: 1.08 | L28: 1.19
B29: Depreciation | I29: 3.23 | J29: 3.47 | K29: 3.4 | L29: 3.4
B30: Sub total | C30: =SUM(C24:C29)+C21 -> 0 | D30: =SUM(D24:D29)+D21 -> 0 | E30: =SUM(E24:E29)+E21 -> 0 | F30: =SUM(F24:F29)+F21 -> 0 | G30: =SUM(G24:G29)+G21 -> 0 | H30: =SUM(H24:H29)+H21 -> 0 | I30: =SUM(I24:I29)+I21 -> 561.03 | J30: =SUM(J24:J29)+J21 -> 460.04 | ... L30: =SUM(L24:L29)+L21 -> 588.71
B31: INCREASE / (DECREASE) IN STOCKS
B32: ADD: Opening Stock in Process
B33: Sub Total | C33: =C30+C32 -> 0 | D33: =D30+D32 -> 0 | E33: =E30+E32 -> 0 | F33: =F30+F32 -> 0 | G33: =G30+G32 -> 0 | H33: =H30+H32 -> 0 | I33: =I30+I32 -> 561.03 | J33: =J30+J32 -> 460.04 | ... L33: =L30+L32 -> 588.71
B34: Deduct: Closing Stock in Process
B35: COST OF PRODUCTION | C35: =C33-C34 -> 0 | D35: =D33-D34 -> 0 | E35: =E33-E34 -> 0 | F35: =F33-F34 -> 0 | G35: =G33-G34 -> 0 | H35: =H33-H34 -> 0 | I35: =I33-I34 -> 561.03 | J35: =J33-J34 -> 460.04 | ... L35: =L33-L34 -> 588.71
B36: ADD: Opening Stock of Finished Goods | I36: 11.09 | J36: 22.59 | K36: 25.66 | L36: 36.36
B37: Sub Total | C37: =C35+C36 -> 0 | D37: =D35+D36 -> 0 | E37: =E35+E36 -> 0 | F37: =F35+F36 -> 0 | G37: =G35+G36 -> 0 | H37: =H35+H36 -> 0 | I37: =I35+I36 -> 572.12 | J37: =J35+J36 -> 482.63 | ... L37: =L35+L36 -> 625.07
B38: LESS: Closing Stock of Finished Goods | I38: 22.59 | J38: 25.66 | K38: 36.36 | L38: 41.34
B39: COST OF SALES | C39: =C37-C38 -> 0 | D39: =D37-D38 -> 0 | E39: =E37-E38 -> 0 | F39: =F37-F38 -> 0 | G39: =G37-G38 -> 0 | H39: =H37-H38 -> 0 | I39: =I37-I38 -> 549.53 | J39: =J37-J38 -> 456.97 | ... L39: =L37-L38 -> 583.73
B40: Selling, General & Admn. Expenses/Fin. Charges | C40: =+SUM(C41:C43) -> 0 | D40: =+SUM(D41:D43) -> 0 | E40: =+SUM(E41:E43) -> 0 | F40: =+SUM(F41:F43) -> 0 | G40: =+SUM(G41:G43) -> 0 | H40: =+SUM(H41:H43) -> 0 | I40: =+SUM(I41:I43) -> 1.92 | J40: =+SUM(J41:J43) -> 3.6 | ... L40: =+SUM(L41:L43) -> 3.62
...

Sheet Sheet3
A1: Column1 | B1: 2023 | C1: 2024 | D1: 2025 | E1: 2026
A2: YEAR ENDING 31ST MARCH | B2: Audited | C2: Audited | D2: Projected | E2: Projected
A3: GROSS SALES | B3: 564.38 | C3: 471.12 | D3: 528.88 | E3: 603.94
A4: Domestic Sales | B4: 564.38 | C4: 471.12 | D4: 528.88 | E4: 603.94
A5: Exports Sales
A6: Other Operating INCOME
A7: TOTAL | B7: 564.38 | C7: 471.12 | D7: 528.88 | E7: 603.94
A8: Less: Excise Duty / taxes
A9: NET SALES | B9: 564.38 | C9: 471.12 | D9: 528.88 | E9: 603.94
A10: % rise/fall in Net Sales compared to Previous Year | B10: #DIV/0! | C10: -0.16524328 | D10: 0.12260146 | E10: 0.14192255
A11: COST OF SALES
A12: Raw Materials consumption | B12: 473.14 | C12: 384.37 | D12: 435.88 | E12: 491.28
A13: a) Import
A14: b) Indigenous | B14: 473.14 | C14: 384.37 | D14: 435.88 | E14: 491.28
A15: Other Spares/packing Material / trading goods | B15: 11.37 | C15: 8.3 | D15: 9.81 | E15: 11.05
A16: Indigenous packing material (Incl. Stores)
A17: Power & Fuel | B17: 71.29 | C17: 61.98 | D17: 70.35 | E17: 80
A18: Direct Cost | B18: 0.8 | C18: 0.89 | D18: 1.63 | E18: 1.79
A19: Other Mfg. Expenses | B19: 1.2 | C19: 1.03 | D19: 1.08 | E19: 1.19
A20: Depreciation | B20: 3.23 | C20: 3.47 | D20: 3.4 | E20: 3.4
A21: Sub total | B21: 561.03 | C21: 460.04 | D21: 522.15 | E21: 588.71
A22: INCREASE / (DECREASE) IN STOCKS
A23: ADD: Opening Stock in Process
A24: Sub Total | B24: 561.03 | C24: 460.04 | D24: 522.15 | E24: 588.71
A25: Deduct: Closing Stock in Process
A26: COST OF PRODUCTION | B26: 561.03 | C26: 460.04 | D26: 522.15 | E26: 588.71
A27: ADD: Opening Stock of Finished Goods | B27: 11.09 | C27: 22.59 | D27: 25.66 | E27: 36.36
A28: Sub Total | B28: 572.12 | C28: 482.63 | D28: 547.81 | E28: 625.07
A29: LESS: Closing Stock of Finished Goods | B29: 22.59 | C29: 25.66 | D29: 36.36 | E29: 41.34
A30: COST OF SALES | B30: 549.53 | C30: 456.97 | D30: 511.45 | E30: 583.73
A31: Selling, General & Admn. Expenses/Fin. Charges | B31: 1.92 | C31: 3.6 | D31: 3.17 | E31: 3.62
A32: a) Selling Expenses
A33: b) General & admin Exp/ Finance Expenses | B33: 1.42 | C33: 3.01 | D33: 3.17 | E33: 3.62
A34: c) Employee Benefit Expenses | B34: 0.5 | C34: 0.59
A35: SUB TOTAL | B35: 551.45 | C35: 460.57 | D35: 514.62 | E35: 587.35
A36: Operating Profit before Interest | B36: 12.93 | C36: 10.55 | D36: 14.26 | E36: 16.59
A37: Interest | B37: 2.45 | C37: 3.69 | D37: 4.8 | E37: 4.71
A38: a) Term Loan (incl. other term liabilities) | B38: 0.5 | C38: 0.6 | D38: 0.21 | E38: 0.12
A39: b) Working Capital | B39: 1.95 | C39: 3.09 | D39: 4.59 | E39: 4.59
A40: c) Other Charges
...

Sheet MPBF
A1: =+'Data Input'!B5 -> Punjab National Bank
A2: =+'Data Input'!B6 -> MCC Durgapur
A3: =+'Data Input'!B7 -> Durgapur
A4: =+'Data Input'!B4 -> H R Ispat Pvt Ltd | B4: =IF('Data Input'!E10="", "", 'Data Input'!E10) -> Audited | C4: =IF('Data Input'!F10="", "", 'Data Input'!F10) -> Audited | D4: =IF('Data Input'!G10="", "", 'Data Input'!G10) -> Audited | E4: =IF('Data Input'!H10="", "", 'Data Input'!H10) -> Audited | F4: =IF('Data Input'!I10="", "", 'Data Input'!I10) -> Audited | G4: =IF('Data Input'!J10="", "", 'Data Input'!J10) -> Audited | H4: =IF('Data Input'!K10="", "", 'Data Input'!K10) -> Projected | I4: =IF('Data Input'!L10="", "", 'Data Input'!L10) -> Projected
B5: =IF('Data Input'!E11="", "", 'Data Input'!E11) -> 2019 | C5: =IF('Data Input'!F11="", "", 'Data Input'!F11) -> 2020 | D5: =IF('Data Input'!G11="", "", 'Data Input'!G11) -> 2021 | E5: =IF('Data Input'!H11="", "", 'Data Input'!H11) -> 2022 | F5: =IF('Data Input'!I11="", "", 'Data Input'!I11) -> 2023 | G5: =IF('Data Input'!J11="", "", 'Data Input'!J11) -> 2024 | H5: =IF('Data Input'!K11="", "", 'Data Input'!K11) -> 2025 | I5: =IF('Data Input'!L11="", "", 'Data Input'!L11) -> 2026
A6: 1. Sales/ Income :-
A7: Gross Sales | B7: ='Data Input'!E12 -> 0 | C7: ='Data Input'!F12 -> 0 | D7: ='Data Input'!G12 -> 0 | E7: ='Data Input'!H12 -> 0 | F7: ='Data Input'!I12 -> 564.38 | G7: ='Data Input'!J12 -> 471.12 | H7: ='Data Input'!K12 -> 528.88 | I7: ='Data Input'!L12 -> 603.94
A8: Net Sales | B8: ='Data Input'!E18 -> 0 | C8: ='Data Input'!F18 -> 0 | D8: ='Data Input'!G18 -> 0 | E8: ='Data Input'!H18 -> 0 | F8: ='Data Input'!I18 -> 564.38 | G8: ='Data Input'!J18 -> 471.12 | H8: ='Data Input'!K18 -> 528.88 | I8: ='Data Input'!L18 -> 603.94
A9: Domestic Sales | B9: ='Data Input'!E13 -> 0 | C9: ='Data Input'!F13 -> 0 | D9: ='Data Input'!G13 -> 0 | E9: ='Data Input'!H13 -> 0 | F9: ='Data Input'!I13 -> 564.38 | G9: ='Data Input'!J13 -> 471.12 | H9: ='Data Input'!K13 -> 528.88 | I9: ='Data Input'!L13 -> 603.94
A10: Export Sales | B10: ='Data Input'!E14 -> 0 | C10: ='Data Input'!F14 -> 0 | D10: ='Data Input'!G14 -> 0 | E10: ='Data Input'!H14 -> 0 | F10: ='Data Input'!I14 -> 0 | G10: ='Data Input'!J14 -> 0 | H10: ='Data Input'!K14 -> 0 | I10: ='Data Input'!L14 -> 0
A11: =+'[1]P & L A'!A16 -> Total Receipts | B11: =+B7+'Data Input'!E51 -> 0 | C11: =+C7+'Data Input'!F51 -> 0 | D11: =+D7+'Data Input'!G51 -> 0 | E11: =+E7+'Data Input'!H51 -> 0 | F11: =+F7+'Data Input'!I51 -> 564.48 | G11: =+G7+'Data Input'!J51 -> 471.27 | H11: =+H7+'Data Input'!K51 -> 528.88 | I11: =+I7+'Data Input'!L51 -> 603.94
A12: Total Expenses | B12: =B11-'Data Input'!E50+'Data Input'!E52 -> 0 | C12: =C11-'Data Input'!F50+'Data Input'!F52 -> 0 | D12: =D11-'Data Input'!G50+'Data Input'!G52 -> 0 | E12: =E11-'Data Input'!H50+'Data Input'!H52 -> 0 | F12: =F11-'Data Input'!I50+'Data Input'!I52 -> 554 | G12: =G11-'Data Input'!J50+'Data Input'!J52 -> 464.41 | H12: =H11-'Data Input'!K50+'Data Input'!K52 -> 519.42 | I12: =I11-'Data Input'!L50+'Data Input'!L52 -> 592.06
A13: Cost of Production | B13: ='Data Input'!E35 -> 0 | C13: ='Data Input'!F35 -> 0 | D13: ='Data Input'!G35 -> 0 | E13: ='Data Input'!H35 -> 0 | F13: ='Data Input'!I35 -> 561.03 | G13: ='Data Input'!J35 -> 460.04 | H13: ='Data Input'!K35 -> 522.15 | I13: ='Data Input'!L35 -> 588.71
A14: Cost of Sales | B14: ='Data Input'!E39 -> 0 | C14: ='Data Input'!F39 -> 0 | D14: ='Data Input'!G39 -> 0 | E14: ='Data Input'!H39 -> 0 | F14: ='Data Input'!I39 -> 549.53 | G14: ='Data Input'!J39 -> 456.97 | H14: ='Data Input'!K39 -> 511.45 | I14: ='Data Input'!L39 -> 583.73
A15: 2. Holding Position :-
A16: 1. Raw Materials & Consumable Spares | B16: ='Data Input'!E113+'Data Input'!E118 -> 0 | C16: ='Data Input'!F113+'Data Input'!F118 -> 0 | D16: ='Data Input'!G113+'Data Input'!G118 -> 0 | E16: ='Data Input'!H113+'Data Input'!H118 -> 0 | F16: ='Data Input'!I113+'Data Input'!I118 -> 13.85 | G16: ='Data Input'!J113+'Data Input'!J118 -> 9.45 | H16: ='Data Input'!K113+'Data Input'!K118 -> 21.08 | I16: ='Data Input'!L113+'Data Input'!L118 -> 24.08
A17: (Month's Consumption) | B17: =(B16*12)/('Data Input'!E21+'Data Input'!E24+'Data Input'!E25) -> #DIV/0! | C17: =(C16*12)/('Data Input'!F21+'Data Input'!F24+'Data Input'!F25) -> #DIV/0! | D17: =(D16*12)/('Data Input'!G21+'Data Input'!G24+'Data Input'!G25) -> #DIV/0! | E17: =E16*12/('Data Input'!H21+'Data Input'!H24+'Data Input'!H25) -> #DIV/0! | F17: =F16*12/('Data Input'!I21+'Data Input'!I24+'Data Input'!I25) -> 0.34302698 | G17: =G16*12/('Data Input'!J21+'Data Input'!J24+'Data Input'!J25) -> 0.28879212 | H17: =H16*12/('Data Input'!K21+'Data Input'!K24+'Data Input'!K25) -> 0.56756939 | I17: =I16*12/('Data Input'!L21+'Data Input'!L24+'Data Input'!L25) -> 0.57523938
A18: 2. Stock In Process | B18: ='Data Input'!E116 -> 0 | C18: ='Data Input'!F116 -> 0 | D18: ='Data Input'!G116 -> 0 | E18: ='Data Input'!H116 -> 0 | F18: ='Data Input'!I116 -> 0 | G18: ='Data Input'!J116 -> 0 | H18: ='Data Input'!K116 -> 0 | I18: ='Data Input'!L116 -> 0
A19: (Month's Cost of Production) | B19: =B18*12/B13 -> #DIV/0! | C19: =C18*12/C13 -> #DIV/0! | D19: =D18*12/D13 -> #DIV/0! | E19: =E18*12/E13 -> #DIV/0! | F19: =F18*12/F13 -> 0 | G19: =G18*12/G13 -> 0 | H19: =H18*12/H13 -> 0 | I19: =I18*12/I13 -> 0
A20: 3. Finished Goods | B20: ='Data Input'!E117 -> 0 | C20: ='Data Input'!F117 -> 0 | D20: ='Data Input'!G117 -> 0 | E20: ='Data Input'!H117 -> 0 | F20: ='Data Input'!I117 -> 22.59 | G20: ='Data Input'!J117 -> 25.66 | H20: ='Data Input'!K117 -> 36.36 | I20: ='Data Input'!L117 -> 41.34
A21: (Month's Cost of Sales) | B21: =B20*12/B14 -> #DIV/0! | C21: =C20*12/C14 -> #DIV/0! | D21: =D20*12/D14 -> #DIV/0! | E21: =E20*12/E14 -> #DIV/0! | F21: =F20*12/F14 -> 0.49329427 | G21: =G20*12/G14 -> 0.67382979 | H21: =H20*12/H14 -> 0.85310392 | I21: =I20*12/I14 -> 0.84984496
A22: 4. Recievables - Domestic | B22: ='Data Input'!E110+'Data Input'!E129 -> 0 | C22: ='Data Input'!F110+'Data Input'!F129 -> 0 | D22: ='Data Input'!G110+'Data Input'!G129 -> 0 | E22: ='Data Input'!H110+'Data Input'!H129 -> 0 | F22: ='Data Input'!I110+'Data Input'!I129 -> 18.81 | G22: ='Data Input'!J110+'Data Input'!J129 -> 30.67 | H22: ='Data Input'!K110+'Data Input'!K129 -> 37.04 | I22: ='Data Input'!L110+'Data Input'!L129 -> 42.29
A23: (Month's Domestic Sales) | B23: =B22*12/B9 -> #DIV/0! | C23: =C22*12/C9 -> #DIV/0! | D23: =D22*12/D9 -> #DIV/0! | E23: =E22*12/E9 -> #DIV/0! | F23: =F22*12/F9 -> 0.3999433 | G23: =G22*12/G9 -> 0.78120224 | H23: =H22*12/H9 -> 0.84041749 | I23: =I22*12/I9 -> 0.84028215
A24: 5. Export Recievables | B24: ='Data Input'!E111 -> 0 | C24: ='Data Input'!F111 -> 0 | D24: ='Data Input'!G111 -> 0 | E24: ='Data Input'!H111 -> 0 | F24: ='Data Input'!I111 -> 0 | G24: ='Data Input'!J111 -> 0 | H24: ='Data Input'!K111 -> 0 | I24: ='Data Input'!L111 -> 0
A25: (Month's Export Sales) | B25: =B24*12/B10 -> #DIV/0! | C25: =C24*12/C10 -> #DIV/0! | D25: =D24*12/D10 -> #DIV/0! | E25: =E24*12/E10 -> #DIV/0! | F25: =F24*12/F10 -> #DIV/0! | G25: =G24*12/G10 -> #DIV/0! | H25: =H24*12/H10 -> #DIV/0! | I25: =I24*12/I10 -> #DIV/0!
A26: 6. Loans & Advances | B26: ='Data Input'!E119+'Data Input'!E120 -> 0 | C26: ='Data Input'!F119+'Data Input'!F120 -> 0 | D26: ='Data Input'!G119+'Data Input'!G120 -> 0 | E26: ='Data Input'!H119+'Data Input'!H120 -> 0 | F26: ='Data Input'!I119+'Data Input'!I120 -> 8.5 | G26: ='Data Input'!J119+'Data Input'!J120 -> 6.8 | H26: ='Data Input'!K119+'Data Input'!K120 -> 16.28 | I26: ='Data Input'!L119+'Data Input'!L120 -> 10.52
A27: 7. All other Current Assets Incl. Cash/ Bank Balance | B27: ='Data Input'!E121+'Data Input'!E105+'Data Input'!E106 -> 0 | C27: ='Data Input'!F121+'Data Input'!F105+'Data Input'!F106 -> 0 | D27: ='Data Input'!G121+'Data Input'!G105+'Data Input'!G106 -> 0 | E27: ='Data Input'!H121+'Data Input'!H105+'Data Input'!H106 -> 0 | F27: ='Data Input'!I121+'Data Input'!I105+'Data Input'!I106 -> 2.81 | G27: ='Data Input'!J121+'Data Input'!J105+'Data Input'!J106 -> 5.02 | H27: ='Data Input'!K121+'Data Input'!K105+'Data Input'!K106 -> 6.17 | I27: ='Data Input'!L121+'Data Input'!L105+'Data Input'!L106 -> 12.16
A28: Total Current Assets | B28: =+B27+B26+B24+B22+B20+B18+B16 -> 0 | C28: =+C27+C26+C24+C22+C20+C18+C16 -> 0 | D28: =+D27+D26+D24+D22+D20+D18+D16 -> 0 | E28: =+E27+E26+E24+E22+E20+E18+E16 -> 0 | F28: =+F27+F26+F24+F22+F20+F18+F16 -> 66.56 | G28: =+G27+G26+G24+G22+G20+G18+G16 -> 77.6 | H28: =+H27+H26+H24+H22+H20+H18+H16 -> 116.93 | I28: =+I27+I26+I24+I22+I20+I18+I16 -> 130.39
A29: 3. Chargeable Current Assets
A30: Raw material | B30: ='Data Input'!E113 -> 0 | C30: ='Data Input'!F113 -> 0 | D30: ='Data Input'!G113 -> 0 | E30: ='Data Input'!H113 -> 0 | F30: ='Data Input'!I113 -> 13.38 | G30: ='Data Input'!J113 -> 8.97 | H30: ='Data Input'!K113 -> 20.1 | I30: ='Data Input'!L113 -> 22.97
A31: Consumable Spares | B31: ='Data Input'!E118 -> 0 | C31: ='Data Input'!F118 -> 0 | D31: ='Data Input'!G118 -> 0 | E31: ='Data Input'!H118 -> 0 | F31: ='Data Input'!I118 -> 0.47 | G31: ='Data Input'!J118 -> 0.48 | H31: ='Data Input'!K118 -> 0.98 | I31: ='Data Input'!L118 -> 1.11
A32: Stock in Process | B32: ='Data Input'!E116 -> 0 | C32: ='Data Input'!F116 -> 0 | D32: ='Data Input'!G116 -> 0 | E32: ='Data Input'!H116 -> 0 | F32: ='Data Input'!I116 -> 0 | G32: ='Data Input'!J116 -> 0 | H32: ='Data Input'!K116 -> 0 | I32: ='Data Input'!L116 -> 0
A33: Finished Goods | B33: ='Data Input'!E117 -> 0 | C33: ='Data Input'!F117 -> 0 | D33: ='Data Input'!G117 -> 0 | E33: ='Data Input'!H117 -> 0 | F33: ='Data Input'!I117 -> 22.59 | G33: ='Data Input'!J117 -> 25.66 | H33: ='Data Input'!K117 -> 36.36 | I33: ='Data Input'!L117 -> 41.34
A34: a. Total Inventory | B34: =SUM(B30:B33) -> 0 | C34: =SUM(C30:C33) -> 0 | D34: =SUM(D30:D33) -> 0 | E34: =SUM(E30:E33) -> 0 | F34: =SUM(F30:F33) -> 36.44 | G34: =SUM(G30:G33) -> 35.11 | H34: =SUM(H30:H33) -> 57.44 | I34: =SUM(I30:I33) -> 65.42
A35: b. Recievables | B35: =B22+B24 -> 0 | C35: =C22+C24 -> 0 | D35: =D22+D24 -> 0 | E35: =E22+E24 -> 0 | F35: =F22+F24 -> 18.81 | G35: =G22+G24 -> 30.67 | H35: =H22+H24 -> 37.04 | I35: =I22+I24 -> 42.29
A36: (Month's Dom. & Exp. Sales) | B36: =B35*12/(B9+B10) -> #DIV/0! | C36: =C35*12/(C9+C10) -> #DIV/0! | D36: =D35*12/(D9+D10) -> #DIV/0! | E36: =E35*12/(E9+E10) -> #DIV/0! | F36: =F35*12/(F9+F10) -> 0.3999433 | G36: =G35*12/(G9+G10) -> 0.78120224 | H36: =H35*12/(H9+H10) -> 0.84041749 | I36: =I35*12/(I9+I10) -> 0.84028215
A37: Total CCA (a+b)
A38: 4. Other Current Assets :-
A39: Cash and Bank Balance | B39: ='Data Input'!E105 -> 0 | C39: ='Data Input'!F105 -> 0 | D39: ='Data Input'!G105 -> 0 | E39: ='Data Input'!H105 -> 0 | F39: ='Data Input'!I105 -> 2.81 | G39: ='Data Input'!J105 -> 5.02 | H39: ='Data Input'!K105 -> 6.17 | I39: ='Data Input'!L105 -> 12.16
A40: Advances to Suppliers | B40: ='Data Input'!E119 -> 0 | C40: ='Data Input'!F119 -> 0 | D40: ='Data Input'!G119 -> 0 | E40: ='Data Input'!H119 -> 0 | F40: ='Data Input'!I119 -> 7.57 | G40: ='Data Input'!J119 -> 6.18 | H40: ='Data Input'!K119 -> 0 | I40: ='Data Input'!L119 -> 0
...

Sheet BSA
A1: =+'Data Input'!B5 -> Punjab National Bank
A2: =+'Data Input'!B6 -> MCC Durgapur
A3: =+'Data Input'!B7 -> Durgapur
A4: =+'Data Input'!B4 -> H R Ispat Pvt Ltd | B4: =IF('Data Input'!C10="", "", 'Data Input'!C10) -> Audited | C4: =IF('Data Input'!D10="", "", 'Data Input'!D10) -> Audited | D4: =IF('Data Input'!E10="", "", 'Data Input'!E10) -> Audited | E4: =IF('Data Input'!F10="", "", 'Data Input'!F10) -> Audited | F4: =IF('Data Input'!G10="", "", 'Data Input'!G10) -> Audited | G4: =IF('Data Input'!H10="", "", 'Data Input'!H10) -> Audited | H4: =IF('Data Input'!I10="", "", 'Data Input'!I10) -> Audited | I4: =IF('Data Input'!J10="", "", 'Data Input'!J10) -> Audited | ... K4: =IF('Data Input'!L10="", "", 'Data Input'!L10) -> Projected
B5: =IF('Data Input'!C11="", "", 'Data Input'!C11) -> 2017 | C5: =IF('Data Input'!D11="", "", 'Data Input'!D11) -> 2018 | D5: =IF('Data Input'!E11="", "", 'Data Input'!E11) -> 2019 | E5: =IF('Data Input'!F11="", "", 'Data Input'!F11) -> 2020 | F5: =IF('Data Input'!G11="", "", 'Data Input'!G11) -> 2021 | G5: =IF('Data Input'!H11="", "", 'Data Input'!H11) -> 2022 | H5: =IF('Data Input'!I11="", "", 'Data Input'!I11) -> 2023 | I5: =IF('Data Input'!J11="", "", 'Data Input'!J11) -> 2024 | ... K5: =IF('Data Input'!L11="", "", 'Data Input'!L11) -> 2026
A6: 1. ROCE CALCULATIONS :-
A7: Profit before tax | B7: ='Data Input'!C54 -> 0 | C7: ='Data Input'!D54 -> 0 | D7: ='Data Input'!E54 -> 0 | E7: ='Data Input'!F54 -> 0 | F7: ='Data Input'!G54 -> 0 | G7: ='Data Input'!H54 -> 0 | H7: ='Data Input'!I54 -> 10.58 | I7: ='Data Input'!J54 -> 7.01 | ... K7: ='Data Input'!L54 -> 12.1
A8: Add long term Interest | B8: ='Data Input'!C47 -> 0 | C8: ='Data Input'!D47 -> 0 | D8: ='Data Input'!E47 -> 0 | E8: ='Data Input'!F47 -> 0 | F8: ='Data Input'!G47 -> 0 | G8: ='Data Input'!H47 -> 0 | H8: ='Data Input'!I47 -> 0.5 | I8: ='Data Input'!J47 -> 0.6 | ... K8: ='Data Input'!L47 -> 0.12
A9: Add Extra ordinary Expenses | B9: ='Data Input'!C52 -> 0 | C9: ='Data Input'!D52 -> 0 | D9: ='Data Input'!E52 -> 0 | E9: ='Data Input'!F52 -> 0 | F9: ='Data Input'!G52 -> 0 | G9: ='Data Input'!H52 -> 0 | H9: ='Data Input'!I52 -> 0 | I9: ='Data Input'!J52 -> 0 | ... K9: ='Data Input'!L52 -> 0
A10: Less Extra ordinary income | B10: ='Data Input'!C51 -> 0 | C10: ='Data Input'!D51 -> 0 | D10: ='Data Input'!E51 -> 0 | E10: ='Data Input'!F51 -> 0 | F10: ='Data Input'!G51 -> 0 | G10: ='Data Input'!H51 -> 0 | H10: ='Data Input'!I51 -> 0.1 | I10: ='Data Input'!J51 -> 0.15 | ... K10: ='Data Input'!L51 -> 0
A11: Adjusted Op PBIT | B11: =B7+B8+B9-B10 -> 0 | C11: =C7+C8+C9-C10 -> 0 | D11: =D7+D8+D9-D10 -> 0 | E11: =E7+E8+E9-E10 -> 0 | F11: =F7+F8+F9-F10 -> 0 | G11: =G7+G8+G9-G10 -> 0 | H11: =H7+H8+H9-H10 -> 10.98 | I11: =I7+I8+I9-I10 -> 7.46 | ... K11: =K7+K8+K9-K10 -> 12.22
A12: Average Capital Employed | B12: ='Data Input'!C101+'Data Input'!C94 -> 0 | C12: ='Data Input'!D101+'Data Input'!D94 -> 0 | D12: ='Data Input'!E101+'Data Input'!E94 -> 0 | E12: ='Data Input'!F101+'Data Input'!F94 -> 0 | F12: ='Data Input'!G101+'Data Input'!G94 -> 0 | G12: ='Data Input'!H101+'Data Input'!H94 -> 0 | H12: ='Data Input'!I101+'Data Input'!I94 -> 50.84 | I12: ='Data Input'!J101+'Data Input'!J94 -> 53.15 | ... K12: ='Data Input'!L101+'Data Input'!L94 -> 66.83
A13: ROCE (%) | B13: =B11/B12 -> #DIV/0! | C13: =C11/C12 -> #DIV/0! | D13: =D11/D12 -> #DIV/0! | E13: =E11/E12 -> #DIV/0! | F13: =F11/F12 -> #DIV/0! | G13: =G11/G12 -> #DIV/0! | H13: =H11/H12 -> 0.21597168 | I13: =I11/I12 -> 0.14035748 | ... K13: =K11/K12 -> 0.18285201
A14: 2. EBIDTA :-
A15: Net profit after tax | B15: ='Data Input'!C57 -> 0 | C15: ='Data Input'!D57 -> 0 | D15: ='Data Input'!E57 -> 0 | E15: ='Data Input'!F57 -> 0 | F15: ='Data Input'!G57 -> 0 | G15: ='Data Input'!H57 -> 0 | H15: ='Data Input'!I57 -> 5.25 | I15: ='Data Input'!J57 -> 4.79 | ... K15: ='Data Input'!L57 -> 8.12
A16: Add: Tax | B16: ='Data Input'!C55+'Data Input'!C56 -> 0 | C16: ='Data Input'!D55+'Data Input'!D56 -> 0 | D16: ='Data Input'!E55+'Data Input'!E56 -> 0 | E16: ='Data Input'!F55+'Data Input'!F56 -> 0 | F16: ='Data Input'!G55+'Data Input'!G56 -> 0 | G16: ='Data Input'!H55+'Data Input'!H56 -> 0 | H16: ='Data Input'!I55+'Data Input'!I56 -> 5.33 | I16: ='Data Input'!J55+'Data Input'!J56 -> 2.22 | ... K16: ='Data Input'!L55+'Data Input'!L56 -> 3.98
A17: Add: Depreciation | B17: ='Data Input'!C29 -> 0 | C17: ='Data Input'!D29 -> 0 | D17: ='Data Input'!E29 -> 0 | E17: ='Data Input'!F29 -> 0 | F17: ='Data Input'!G29 -> 0 | G17: ='Data Input'!H29 -> 0 | H17: ='Data Input'!I29 -> 3.23 | I17: ='Data Input'!J29 -> 3.47 | ... K17: ='Data Input'!L29 -> 3.4
A18: Add: Interest | B18: ='Data Input'!C46 -> 0 | C18: ='Data Input'!D46 -> 0 | D18: ='Data Input'!E46 -> 0 | E18: ='Data Input'!F46 -> 0 | F18: ='Data Input'!G46 -> 0 | G18: ='Data Input'!H46 -> 0 | H18: ='Data Input'!I46 -> 2.45 | I18: ='Data Input'!J46 -> 3.69 | ... K18: ='Data Input'!L46 -> 4.71
A19: EBIDTA | B19: =SUM(B15:B18) -> 0 | C19: =SUM(C15:C18) -> 0 | D19: =SUM(D15:D18) -> 0 | E19: =SUM(E15:E18) -> 0 | F19: =SUM(F15:F18) -> 0 | G19: =SUM(G15:G18) -> 0 | H19: =SUM(H15:H18) -> 16.26 | I19: =SUM(I15:I18) -> 14.17 | ... K19: =SUM(K15:K18) -> 20.21
A20: PBDIT | B20: =B15+B16+B17 -> 0 | C20: =C15+C16+C17 -> 0 | D20: =D15+D16+D17 -> 0 | E20: =E15+E16+E17 -> 0 | F20: =F15+F16+F17 -> 0 | G20: =G15+G16+G17 -> 0 | H20: =H15+H16+H17 -> 13.81 | I20: =I15+I16+I17 -> 10.48 | ... K20: =K15+K16+K17 -> 15.5
A21: 3. GROWTH :-
A22: Gross Sales | B22: ='Data Input'!C12 -> 0 | C22: ='Data Input'!D12 -> 0 | D22: ='Data Input'!E12 -> 0 | E22: ='Data Input'!F12 -> 0 | F22: ='Data Input'!G12 -> 0 | G22: ='Data Input'!H12 -> 0 | H22: ='Data Input'!I12 -> 564.38 | I22: ='Data Input'!J12 -> 471.12 | ... K22: ='Data Input'!L12 -> 603.94
A23: Total Net Sales | B23: ='Data Input'!C18 -> 0 | C23: ='Data Input'!D18 -> 0 | D23: ='Data Input'!E18 -> 0 | E23: ='Data Input'!F18 -> 0 | F23: ='Data Input'!G18 -> 0 | G23: ='Data Input'!H18 -> 0 | H23: ='Data Input'!I18 -> 564.38 | I23: ='Data Input'!J18 -> 471.12 | ... K23: ='Data Input'!L18 -> 603.94
A24: Domestic Sales | B24: ='Data Input'!C13 -> 0 | C24: ='Data Input'!D13 -> 0 | D24: ='Data Input'!E13 -> 0 | E24: ='Data Input'!F13 -> 0 | F24: ='Data Input'!G13 -> 0 | G24: ='Data Input'!H13 -> 0 | H24: ='Data Input'!I13 -> 564.38 | I24: ='Data Input'!J13 -> 471.12 | ... K24: ='Data Input'!L13 -> 603.94
A25: Exports Sales | B25: ='Data Input'!C14 -> 0 | C25: ='Data Input'!D14 -> 0 | D25: ='Data Input'!E14 -> 0 | E25: ='Data Input'!F14 -> 0 | F25: ='Data Input'!G14 -> 0 | G25: ='Data Input'!H14 -> 0 | H25: ='Data Input'!I14 -> 0 | I25: ='Data Input'!J14 -> 0 | ... K25: ='Data Input'!L14 -> 0
A26: Growth in Sales (net %) | B26: - | C26: =(C23-B23)/B23 -> #DIV/0! | D26: =(D23-C23)/C23 -> #DIV/0! | E26: =(E23-D23)/D23 -> #DIV/0! | F26: =(F23-E23)/E23 -> #DIV/0! | G26: =(G23-F23)/F23 -> #DIV/0! | H26: =(H23-G23)/G23 -> #DIV/0! | I26: =(I23-H23)/H23 -> -0.16524328 | J26: =(J23-I23)/I23 -> 0.12260146 | K26: =(K23-J23)/J23 -> 0.14192255
A27: 4. Profitability :-
A28: PBT/Net sales(%) | B28: =B7/B23 -> #DIV/0! | C28: =C7/C23 -> #DIV/0! | D28: =D7/D23 -> #DIV/0! | E28: =E7/E23 -> #DIV/0! | F28: =F7/F23 -> #DIV/0! | G28: =G7/G23 -> #DIV/0! | H28: =H7/H23 -> 0.018746235 | I28: =I7/I23 -> 0.014879436 | ... K28: =K7/K23 -> 0.020035103
A29: ROCE (%) | B29: =B13 -> #DIV/0! | C29: =C13 -> #DIV/0! | D29: =D13 -> #DIV/0! | E29: =E13 -> #DIV/0! | F29: =F13 -> #DIV/0! | G29: =G13 -> #DIV/0! | H29: =H13 -> 0.21597168 | I29: =I13 -> 0.14035748 | ... K29: =K13 -> 0.18285201
A30: 5. SOLVENCY :-
A31: Paid up share capital | B31: ='Data Input'!C96 -> 0 | C31: ='Data Input'!D96 -> 0 | D31: ='Data Input'!E96 -> 0 | E31: ='Data Input'!F96 -> 0 | F31: ='Data Input'!G96 -> 0 | G31: ='Data Input'!H96 -> 0 | H31: ='Data Input'!I96 -> 5.33 | I31: ='Data Input'!J96 -> 5.33 | ... K31: ='Data Input'!L96 -> 5.33
A32: Reserves & Surplus (excluding Revaluation reserve) | B32: ='Data Input'!C97+'Data Input'!C100+'Data Input'!C98 -> 0 | C32: ='Data Input'!D97+'Data Input'!D100+'Data Input'!D98 -> 0 | D32: ='Data Input'!E97+'Data Input'!E100+'Data Input'!E98 -> 0 | E32: ='Data Input'!F97+'Data Input'!F100+'Data Input'!F98 -> 0 | F32: ='Data Input'!G97+'Data Input'!G100+'Data Input'!G98 -> 0 | G32: ='Data Input'!H97+'Data Input'!H100+'Data Input'!H98 -> 0 | H32: ='Data Input'!I97+'Data Input'!I100+'Data Input'!I98 -> 31.83 | I32: ='Data Input'!J97+'Data Input'!J100+'Data Input'!J98 -> 36.62 | ... K32: ='Data Input'!L97+'Data Input'!L100+'Data Input'!L98 -> 51.58
A33: Accumulated losses & Intangible assets | B33: ='Data Input'!C136 -> 0 | C33: ='Data Input'!D136 -> 0 | D33: ='Data Input'!E136 -> 0 | E33: ='Data Input'!F136 -> 0 | F33: ='Data Input'!G136 -> 0 | G33: ='Data Input'!H136 -> 0 | H33: ='Data Input'!I136 -> 0 | I33: ='Data Input'!J136 -> 0 | ... K33: ='Data Input'!L136 -> 0
A34: Investments outside business | B34: ='Data Input'!C130 -> 0 | C34: ='Data Input'!D130 -> 0 | D34: ='Data Input'!E130 -> 0 | E34: ='Data Input'!F130 -> 0 | F34: ='Data Input'!G130 -> 0 | G34: ='Data Input'!H130 -> 0 | H34: ='Data Input'!I130 -> 0 | I34: ='Data Input'!J130 -> 0 | ... K34: ='Data Input'!L130 -> 0
A35: Investment in Associate Concern | B35: ='Data Input'!C131 -> 0 | C35: ='Data Input'!D131 -> 0 | D35: ='Data Input'!E131 -> 0 | E35: ='Data Input'!F131 -> 0 | F35: ='Data Input'!G131 -> 0 | G35: ='Data Input'!H131 -> 0 | H35: ='Data Input'!I131 -> 0 | I35: ='Data Input'!J131 -> 0 | ... K35: ='Data Input'!L131 -> 0
A36: Deffered tax liability (Asset) | B36: =+'Data Input'!C99 -> 0 | C36: =+'Data Input'!D99 -> 0 | D36: =+'Data Input'!E99 -> 0 | E36: =+'Data Input'!F99 -> 0 | F36: =+'Data Input'!G99 -> 0 | G36: =+'Data Input'!H99 -> 0 | H36: =+'Data Input'!I99 -> 2 | I36: =+'Data Input'!J99 -> 2.22 | ... K36: =+'Data Input'!L99 -> 2.91
A37: Net Owned Funds | B37: =B31+B32-B33-B34-B35+B36 -> 0 | C37: =C31+C32-C33-C34-C35+C36 -> 0 | D37: =D31+D32-D33-D34-D35+D36 -> 0 | E37: =E31+E32-E33-E34-E35+E36 -> 0 | F37: =F31+F32-F33-F34-F35+F36 -> 0 | G37: =G31+G32-G33-G34-G35+G36 -> 0 | H37: =H31+H32-H33-H34-H35+H36 -> 39.16 | I37: =I31+I32-I33-I34-I35+I36 -> 44.17 | ... K37: =K31+K32-K33-K34-K35+K36 -> 59.82
A38: Tangible Net Worth | B38: =B31+B32+B36-B33 -> 0 | C38: =C31+C32+C36-C33 -> 0 | D38: =D31+D32+D36-D33 -> 0 | E38: =E31+E32+E36-E33 -> 0 | F38: =F31+F32+F36-F33 -> 0 | G38: =G31+G32+G36-G33 -> 0 | H38: =H31+H32+H36-H33 -> 39.16 | I38: =I31+I32+I36-I33 -> 44.17 | ... K38: =K31+K32+K36-K33 -> 59.82
A39: Debt / Equity ratio | B39: ='Data Input'!C94/B38 -> #DIV/0! | C39: ='Data Input'!D94/C38 -> #DIV/0! | D39: ='Data Input'!E94/D38 -> #DIV/0! | E39: ='Data Input'!F94/E38 -> #DIV/0! | F39: ='Data Input'!G94/F38 -> #DIV/0! | G39: ='Data Input'!H94/G38 -> #DIV/0! | H39: ='Data Input'!I94/H38 -> 0.29826353 | I39: ='Data Input'!J94/I38 -> 0.20330541 | ... K39: ='Data Input'!L94/K38 -> 0.11718489
A40: TOL/TNW | B40: ='Data Input'!C95/BSA!B38 -> #DIV/0! | C40: ='Data Input'!D95/BSA!C38 -> #DIV/0! | D40: ='Data Input'!E95/BSA!D38 -> #DIV/0! | E40: ='Data Input'!F95/BSA!E38 -> #DIV/0! | F40: ='Data Input'!G95/BSA!F38 -> #DIV/0! | G40: ='Data Input'!H95/BSA!G38 -> #DIV/0! | H40: ='Data Input'!I95/BSA!H38 -> 1.6797753 | I40: ='Data Input'!J95/BSA!I38 -> 1.5453928 | ... K40: ='Data Input'!L95/BSA!K38 -> 1.648111
...

Sheet 7A
A1: =+'Data Input'!B5 -> Punjab National Bank
A2: =+'Data Input'!B6 -> MCC Durgapur
A3: =+'Data Input'!B7 -> Durgapur
A4: =+'Data Input'!B4 -> H R Ispat Pvt Ltd | B4: =IF('Data Input'!E10="", "", 'Data Input'!E10) -> Audited | C4: =IF('Data Input'!F10="", "", 'Data Input'!F10) -> Audited | D4: =IF('Data Input'!G10="", "", 'Data Input'!G10) -> Audited | E4: =IF('Data Input'!H10="", "", 'Data Input'!H10) -> Audited | F4: =IF('Data Input'!I10="", "", 'Data Input'!I10) -> Audited | G4: =IF('Data Input'!J10="", "", 'Data Input'!J10) -> Audited | H4: =IF('Data Input'!K10="", "", 'Data Input'!K10) -> Projected | I4: =IF('Data Input'!L10="", "", 'Data Input'!L10) -> Projected
B5: =IF('Data Input'!E11="", "", 'Data Input'!E11) -> 2019 | C5: =IF('Data Input'!F11="", "", 'Data Input'!F11) -> 2020 | D5: =IF('Data Input'!G11="", "", 'Data Input'!G11) -> 2021 | E5: =IF('Data Input'!H11="", "", 'Data Input'!H11) -> 2022 | F5: =IF('Data Input'!I11="", "", 'Data Input'!I11) -> 2023 | G5: =IF('Data Input'!J11="", "", 'Data Input'!J11) -> 2024 | H5: =IF('Data Input'!K11="", "", 'Data Input'!K11) -> 2025 | I5: =IF('Data Input'!L11="", "", 'Data Input'!L11) -> 2026
A6: Gross Sales | B6: =+BSA!D22 -> 0 | C6: =+BSA!E22 -> 0 | D6: =+BSA!F22 -> 0 | E6: =+BSA!G22 -> 0 | F6: =+BSA!H22 -> 564.38 | G6: =+BSA!I22 -> 471.12 | H6: =+BSA!J22 -> 528.88 | I6: =+BSA!K22 -> 603.94
A7: - Domestic | B7: =+BSA!D24 -> 0 | C7: =+BSA!E24 -> 0 | D7: =+BSA!F24 -> 0 | E7: =+BSA!G24 -> 0 | F7: =+BSA!H24 -> 564.38 | G7: =+BSA!I24 -> 471.12 | H7: =+BSA!J24 -> 528.88 | I7: =+BSA!K24 -> 603.94
A8: - Export | B8: =+BSA!D25 -> 0 | C8: =+BSA!E25 -> 0 | D8: =+BSA!F25 -> 0 | E8: =+BSA!G25 -> 0 | F8: =+BSA!H25 -> 0 | G8: =+BSA!I25 -> 0 | H8: =+BSA!J25 -> 0 | I8: =+BSA!K25 -> 0
A9: % growth | B9: =+BSA!D26 -> #DIV/0! | C9: =+BSA!E26 -> #DIV/0! | D9: =+BSA!F26 -> #DIV/0! | E9: =+BSA!G26 -> #DIV/0! | F9: =+BSA!H26 -> #DIV/0! | G9: =+BSA!I26 -> -0.16524328 | H9: =+BSA!J26 -> 0.12260146 | I9: =+BSA!K26 -> 0.14192255
A10: Net Sales | B10: =+BSA!D23-B13 -> 0 | C10: =+BSA!E23-C13 -> 0 | D10: =+BSA!F23-D13 -> 0 | E10: =+BSA!G23-E13 -> 0 | F10: =+BSA!H23-F13 -> 564.38 | G10: =+BSA!I23-G13 -> 471.12 | H10: =+BSA!J23-H13 -> 528.88 | I10: =+BSA!K23-I13 -> 603.94
A11: Raw material consumed | B11: ='Data Input'!E23 -> 0 | C11: ='Data Input'!F23 -> 0 | D11: ='Data Input'!G23 -> 0 | E11: ='Data Input'!H23 -> 0 | F11: ='Data Input'!I23 -> 473.14 | G11: ='Data Input'!J23 -> 384.37 | H11: ='Data Input'!K23 -> 435.88 | I11: ='Data Input'!L23 -> 491.28
A12: Purchase of Stock-In trade for Resale | B12: ='Data Input'!E24 -> 0 | C12: ='Data Input'!F24 -> 0 | D12: ='Data Input'!G24 -> 0 | E12: ='Data Input'!H24 -> 0 | F12: ='Data Input'!I24 -> 11.37 | G12: ='Data Input'!J24 -> 8.3 | H12: ='Data Input'!K24 -> 9.81 | I12: ='Data Input'!L24 -> 11.05
A13: Other Operating Income | B13: ='Data Input'!E15 -> 0 | C13: ='Data Input'!F15 -> 0 | D13: ='Data Input'!G15 -> 0 | E13: ='Data Input'!H15 -> 0 | F13: ='Data Input'!I15 -> 0 | G13: ='Data Input'!J15 -> 0 | H13: ='Data Input'!K15 -> 0 | I13: ='Data Input'!L15 -> 0 | J13: =+F13+F14 -> 0.1 | K13: =+G13+G14 -> 0.15
A14: Other Non operating Income | B14: ='Data Input'!E51 -> 0 | C14: ='Data Input'!F51 -> 0 | D14: ='Data Input'!G51 -> 0 | E14: ='Data Input'!H51 -> 0 | F14: ='Data Input'!I51 -> 0.1 | G14: ='Data Input'!J51 -> 0.15 | H14: ='Data Input'!K51 -> 0 | I14: ='Data Input'!L51 -> 0
A15: Operating Profit/Loss | B15: ='Data Input'!E50 -> 0 | C15: ='Data Input'!F50 -> 0 | D15: ='Data Input'!G50 -> 0 | E15: ='Data Input'!H50 -> 0 | F15: ='Data Input'!I50 -> 10.48 | G15: ='Data Input'!J50 -> 6.86 | H15: ='Data Input'!K50 -> 9.46 | I15: ='Data Input'!L50 -> 11.88
A16: Profit before tax | B16: ='Data Input'!E54 -> 0 | C16: ='Data Input'!F54 -> 0 | D16: ='Data Input'!G54 -> 0 | E16: ='Data Input'!H54 -> 0 | F16: ='Data Input'!I54 -> 10.58 | G16: ='Data Input'!J54 -> 7.01 | H16: ='Data Input'!K54 -> 9.66 | I16: ='Data Input'!L54 -> 12.1
A17: Profit after tax | B17: ='Data Input'!E57 -> 0 | C17: ='Data Input'!F57 -> 0 | D17: ='Data Input'!G57 -> 0 | E17: ='Data Input'!H57 -> 0 | F17: ='Data Input'!I57 -> 5.25 | G17: ='Data Input'!J57 -> 4.79 | H17: ='Data Input'!K57 -> 6.84 | I17: ='Data Input'!L57 -> 8.12
A18: Depreciation / Amortization of expenses | B18: ='Data Input'!E29 -> 0 | C18: ='Data Input'!F29 -> 0 | D18: ='Data Input'!G29 -> 0 | E18: ='Data Input'!H29 -> 0 | F18: ='Data Input'!I29 -> 3.23 | G18: ='Data Input'!J29 -> 3.47 | H18: ='Data Input'!K29 -> 3.4 | I18: ='Data Input'!L29 -> 3.4
A19: Cash profit | B19: ='Data Input'!E57+'Data Input'!E29+'Data Input'!E56 -> 0 | C19: ='Data Input'!F57+'Data Input'!F29+'Data Input'!F56 -> 0 | D19: ='Data Input'!G57+'Data Input'!G29+'Data Input'!G56 -> 0 | E19: ='Data Input'!H57+'Data Input'!H29+'Data Input'!H56 -> 0 | F19: ='Data Input'!I57+'Data Input'!I29+'Data Input'!I56 -> 8.48 | G19: ='Data Input'!J57+'Data Input'!J29+'Data Input'!J56 -> 8.26 | H19: ='Data Input'!K57+'Data Input'!K29+'Data Input'!K56 -> 10.24 | I19: ='Data Input'!L57+'Data Input'!L29+'Data Input'!L56 -> 11.52
A20: EBIDTA / PBIDTA | B20: =BSA!D19 -> 0 | C20: =BSA!E19 -> 0 | D20: =BSA!F19 -> 0 | E20: =BSA!G19 -> 0 | F20: =BSA!H19 -> 16.26 | G20: =BSA!I19 -> 14.17 | H20: =BSA!J19 -> 17.86 | I20: =BSA!K19 -> 20.21
A21: Paid up capital | B21: ='Data Input'!E96 -> 0 | C21: ='Data Input'!F96 -> 0 | D21: ='Data Input'!G96 -> 0 | E21: ='Data Input'!H96 -> 0 | F21: ='Data Input'!I96 -> 5.33 | G21: ='Data Input'!J96 -> 5.33 | H21: ='Data Input'!K96 -> 5.33 | I21: ='Data Input'!L96 -> 5.33
A22: Reserves and Surplus / Other equity excluding revaluation reserves | B22: ='Data Input'!E97+'Data Input'!E100+'Data Input'!E98 -> 0 | C22: ='Data Input'!F97+'Data Input'!F100+'Data Input'!F98 -> 0 | D22: ='Data Input'!G97+'Data Input'!G100+'Data Input'!G98 -> 0 | E22: ='Data Input'!H97+'Data Input'!H100+'Data Input'!H98 -> 0 | F22: ='Data Input'!I97+'Data Input'!I100+'Data Input'!I98 -> 31.83 | G22: ='Data Input'!J97+'Data Input'!J100+'Data Input'!J98 -> 36.62 | H22: ='Data Input'!K97+'Data Input'!K100+'Data Input'!K98 -> 43.46 | I22: ='Data Input'!L97+'Data Input'!L100+'Data Input'!L98 -> 51.58
A23: Intangible Assets / Misc assets not witten off | B23: ='Data Input'!E136 -> 0 | C23: ='Data Input'!F136 -> 0 | D23: ='Data Input'!G136 -> 0 | E23: ='Data Input'!H136 -> 0 | F23: ='Data Input'!I136 -> 0 | G23: ='Data Input'!J136 -> 0 | H23: ='Data Input'!K136 -> 0 | I23: ='Data Input'!L136 -> 0
A24: Accumulated losses | B24: 0 | C24: 0 | D24: 0 | E24: 0 | F24: 0 | G24: 0 | H24: 0 | I24: 0
A25: Deferred Tax Liability/Asset | B25: ='Data Input'!E99 -> 0 | C25: ='Data Input'!F99 -> 0 | D25: ='Data Input'!G99 -> 0 | E25: ='Data Input'!H99 -> 0 | F25: ='Data Input'!I99 -> 2 | G25: ='Data Input'!J99 -> 2.22 | H25: ='Data Input'!K99 -> 2.48 | I25: ='Data Input'!L99 -> 2.91
A26: a) Tangible Net Worth | B26: ='Data Input'!E101 -> 0 | C26: ='Data Input'!F101 -> 0 | D26: ='Data Input'!G101 -> 0 | E26: ='Data Input'!H101 -> 0 | F26: ='Data Input'!I101 -> 39.16 | G26: ='Data Input'!J101 -> 44.17 | H26: ='Data Input'!K101 -> 51.27 | I26: ='Data Input'!L101 -> 59.82
A27: b) Investment in allied concerns and amount of cross holdings | B27: ='Data Input'!E130 -> 0 | C27: ='Data Input'!F130 -> 0 | D27: ='Data Input'!G130 -> 0 | E27: ='Data Input'!H130 -> 0 | F27: ='Data Input'!I130 -> 0 | G27: ='Data Input'!J130 -> 0 | H27: ='Data Input'!K130 -> 0 | I27: ='Data Input'!L130 -> 0
A28: c) Net owned funds (a –b) | B28: =B26-B27 -> 0 | C28: =C26-C27 -> 0 | D28: =D26-D27 -> 0 | E28: =E26-E27 -> 0 | F28: =F26-F27 -> 39.16 | G28: =G26-G27 -> 44.17 | H28: =H26-H27 -> 51.27 | I28: =I26-I27 -> 59.82
A29: Loan to allied / asscoiate concern | B29: ='Data Input'!E132 -> 0 | C29: ='Data Input'!F132 -> 0 | D29: ='Data Input'!G132 -> 0 | E29: ='Data Input'!H132 -> 0 | F29: ='Data Input'!I132 -> 0 | G29: ='Data Input'!J132 -> 0 | H29: ='Data Input'!K132 -> 0 | I29: ='Data Input'!L132 -> 0
A30: Share application money | B30: ='Data Input'!E82 -> 0 | C30: ='Data Input'!F82 -> 0 | D30: ='Data Input'!G82 -> 0 | E30: ='Data Input'!H82 -> 0 | F30: ='Data Input'!I82 -> 0 | G30: ='Data Input'!J82 -> 0 | H30: ='Data Input'!K82 -> 0 | I30: ='Data Input'!L82 -> 0
A31: Total Borrowings | B31: ='Data Input'!E94+'Data Input'!E74+'Data Input'!E79+'Data Input'!E82-'Data Input'!E88 -> 0 | C31: ='Data Input'!F94+'Data Input'!F74+'Data Input'!F79+'Data Input'!F82-'Data Input'!F88 -> 0 | D31: ='Data Input'!G94+'Data Input'!G74+'Data Input'!G79+'Data Input'!G82-'Data Input'!G88 -> 0 | E31: ='Data Input'!H94+'Data Input'!H74+'Data Input'!H79+'Data Input'!H82-'Data Input'!H88 -> 0 | F31: ='Data Input'!I94+'Data Input'!I74+'Data Input'!I79+'Data Input'!I82-'Data Input'!I88 -> 33.25 | G31: ='Data Input'!J94+'Data Input'!J74+'Data Input'!J79+'Data Input'!J82-'Data Input'!J88 -> 45.88 | H31: ='Data Input'!K94+'Data Input'!K74+'Data Input'!K79+'Data Input'!K82-'Data Input'!K88 -> 79.05 | I31: ='Data Input'!L94+'Data Input'!L74+'Data Input'!L79+'Data Input'!L82-'Data Input'!L88 -> 78.03
A32: Secured | B32: ='Data Input'!E89+'Data Input'!E91+'Data Input'!E74+'Data Input'!E79 -> 0 | C32: ='Data Input'!F89+'Data Input'!F91+'Data Input'!F74+'Data Input'!F79 -> 0 | D32: ='Data Input'!G89+'Data Input'!G91+'Data Input'!G74+'Data Input'!G79 -> 0 | E32: ='Data Input'!H89+'Data Input'!H91+'Data Input'!H74+'Data Input'!H79 -> 0 | F32: ='Data Input'!I89+'Data Input'!I91+'Data Input'!I74+'Data Input'!I79 -> 25.3 | G32: ='Data Input'!J89+'Data Input'!J91+'Data Input'!J74+'Data Input'!J79 -> 38.98 | H32: ='Data Input'!K89+'Data Input'!K91+'Data Input'!K74+'Data Input'!K79 -> 72.15 | I32: ='Data Input'!L89+'Data Input'!L91+'Data Input'!L74+'Data Input'!L79 -> 71.13
A33: Unsecured | B33: ='Data Input'!E93+'Data Input'!E90+'Data Input'!E92 -> 0 | C33: ='Data Input'!F93+'Data Input'!F90+'Data Input'!F92 -> 0 | D33: ='Data Input'!G93+'Data Input'!G90+'Data Input'!G92 -> 0 | E33: ='Data Input'!H93+'Data Input'!H90+'Data Input'!H92 -> 0 | F33: ='Data Input'!I93+'Data Input'!I90+'Data Input'!I92 -> 7.95 | G33: ='Data Input'!J93+'Data Input'!J90+'Data Input'!J92 -> 6.9 | H33: ='Data Input'!K93+'Data Input'!K90+'Data Input'!K92 -> 6.9 | I33: ='Data Input'!L93+'Data Input'!L90+'Data Input'!L92 -> 6.9
A34: Other investments (excluding investments in allied concerns considered for arriving at Net Owned Funds) | B34: ='Data Input'!E128+'Data Input'!E130 -> 0 | C34: ='Data Input'!F128+'Data Input'!F130 -> 0 | D34: ='Data Input'!G128+'Data Input'!G130 -> 0 | E34: ='Data Input'!H128+'Data Input'!H130 -> 0 | F34: ='Data Input'!I128+'Data Input'!I130 -> 0.03 | G34: ='Data Input'!J128+'Data Input'!J130 -> 0.03 | H34: ='Data Input'!K128+'Data Input'!K130 -> 0.03 | I34: ='Data Input'!L128+'Data Input'!L130 -> 0.03
A35: Total Assets | B35: ='Data Input'!E137 -> 0 | C35: ='Data Input'!F137 -> 0 | D35: ='Data Input'!G137 -> 0 | E35: ='Data Input'!H137 -> 0 | F35: ='Data Input'!I137 -> 104.94 | G35: ='Data Input'!J137 -> 112.43 | H35: ='Data Input'!K137 -> 148.35 | I35: ='Data Input'!L137 -> 158.41
A36: Current Assets | B36: ='Data Input'!E122 -> 0 | C36: ='Data Input'!F122 -> 0 | D36: ='Data Input'!G122 -> 0 | E36: ='Data Input'!H122 -> 0 | F36: ='Data Input'!I122 -> 66.56 | G36: ='Data Input'!J122 -> 77.6 | H36: ='Data Input'!K122 -> 116.93 | I36: ='Data Input'!L122 -> 130.39
A37: Non Current Assets | B37: ='Data Input'!E135 -> 0 | C37: ='Data Input'!F135 -> 0 | D37: ='Data Input'!G135 -> 0 | E37: ='Data Input'!H135 -> 0 | F37: ='Data Input'!I135 -> 4.09 | G37: ='Data Input'!J135 -> 0.04 | H37: ='Data Input'!K135 -> 0.03 | I37: ='Data Input'!L135 -> 0.03
A38: Out of which net fixed assets | B38: ='Data Input'!E126 -> 0 | C38: ='Data Input'!F126 -> 0 | D38: ='Data Input'!G126 -> 0 | E38: ='Data Input'!H126 -> 0 | F38: ='Data Input'!I126 -> 34.29 | G38: ='Data Input'!J126 -> 34.79 | H38: ='Data Input'!K126 -> 31.39 | I38: ='Data Input'!L126 -> 27.99
A39: Current Liabilities | B39: ='Data Input'!E86 -> 0 | C39: ='Data Input'!F86 -> 0 | D39: ='Data Input'!G86 -> 0 | E39: ='Data Input'!H86 -> 0 | F39: ='Data Input'!I86 -> 54.1 | G39: ='Data Input'!J86 -> 59.28 | H39: ='Data Input'!K86 -> 89.05 | I39: ='Data Input'!L86 -> 91.58
A40: Net Working Capital | B40: ='Data Input'!E139 -> 0 | C40: ='Data Input'!F139 -> 0 | D40: ='Data Input'!G139 -> 0 | E40: ='Data Input'!H139 -> 0 | F40: ='Data Input'!I139 -> 12.46 | G40: ='Data Input'!J139 -> 18.32 | H40: ='Data Input'!K139 -> 27.88 | I40: ='Data Input'!L139 -> 38.81
...

Sheet COP-MOF
A1: =+'Data Input'!B5 -> Punjab National Bank | G1: =+'Data Input'!B5 -> Punjab National Bank
A2: =+'Data Input'!B6 -> MCC Durgapur | G2: =+'Data Input'!B6 -> MCC Durgapur
A3: =+'Data Input'!B7 -> Durgapur | G3: =+'Data Input'!B7 -> Durgapur
A4: =+'Data Input'!B4 -> H R Ispat Pvt Ltd | G4: =+'Data Input'!B4 -> H R Ispat Pvt Ltd
A5: COST OF PROJECT | G5: List of Machinery
A6: Particulars | B6: Amt. | C6: Margin (%) | D6: Margin | E6: Elg. Loan | G6: S. No. | H6: Name of Machine | I6: Supplier | J6: Quot No. | K6: No. of Set | L6: Basic Cost/ Pc | M6: Total Basic Cost | N6: Tax | O6: Total
A7: Land | C7: 0.4 | D7: =IF(B7="", "", B7*C7) | E7: 0
A8: Building | C8: 0.25 | D8: =IF(B8="", "", B8*C8) | E8: =B8-D8 -> #VALUE!
A9: Plant & Machinery | C9: 0.05 | D9: =IF(B9="", "", B9*C9) | E9: =B9-D9 -> #VALUE!
A10: Others | C10: 0.25 | D10: =IF(B10="", "", B10*C10) | E10: =B10-D10 -> #VALUE!
A11: Misc. | C11: 0.25 | D11: =IF(B11="", "", B11*C11) | E11: =B11-D11 -> #VALUE!
A12: Total Hard Cost | B12: =IF(SUM(B7:B11)=0, "", SUM(B7:B11)) | D12: =IF(SUM(D7:D11)=0, "", SUM(D7:D11)) | E12: =IF(SUM(E7:E11)=0, "", SUM(E7:E11)) -> #VALUE!
A13: Interest During Construction | C13: 0
A14: Contingency | C14: 0
A15: Other Prelim. Pre-Op Expenses | C15: 0
A16: Total Cost | B16: =IF(SUM(B12:B15)=0, "", SUM(B12:B15)) | D16: =IF(SUM(D12:D15)=0, "", SUM(D12:D15)) | E16: =IF(SUM(E12:E15)=0, "", SUM(E12:E15)) -> #VALUE!
A17: MEANS OF FINANCE
A18: Particulars | B18: Amt. | C18: %age
A19: Promoter's Margin | C19: =IF(B19/B16="", "", B19/B16) -> #VALUE!
A20: Share Capital | C20: =IF(B20/B16="", "", B20/B16) -> #VALUE!
A21: Internal Accrual | C21: =IF(B21/B16="", "", B21/B16) -> #VALUE!
A22: Unsecured Loans | C22: =IF(B22/B16="", "", B22/B16) -> #VALUE!
A23: Preference shares | C23: =IF(B23/B16="", "", B23/B16) -> #VALUE!
A24: Bank Loan | C24: =B24/B16 -> #VALUE!
A25: Other Third Party Sources | C25: =B25/B16 -> #VALUE!
A26: Total Means of Finance | B26: =IF(SUM(B20:B25)=0, "", SUM(B20:B25))

Sheet DSCR & IRR
A1: =+'Data Input'!B5 -> Punjab National Bank
A2: =+'Data Input'!B6 -> MCC Durgapur
A3: =+'Data Input'!B7 -> Durgapur
A4: =+'Data Input'!B4 -> H R Ispat Pvt Ltd
A5: DSCR CALCULATION | B5: =IF('Data Input'!I10="", "", 'Data Input'!I10) -> Audited | C5: =IF('Data Input'!J10="", "", 'Data Input'!J10) -> Audited | D5: =IF('Data Input'!K10="", "", 'Data Input'!K10) -> Projected | E5: =IF('Data Input'!L10="", "", 'Data Input'!L10) -> Projected | F5: =IF('Data Input'!#REF!="", "", 'Data Input'!#REF!) -> #REF! | G5: =IF('Data Input'!#REF!="", "", 'Data Input'!#REF!) -> #REF! | H5: =IF('Data Input'!#REF!="", "", 'Data Input'!#REF!) -> #REF! | I5: =IF('Data Input'!#REF!="", "", 'Data Input'!#REF!) -> #REF! | J5: =IF('Data Input'!#REF!="", "", 'Data Input'!#REF!) -> #REF! | K5: =IF('Data Input'!#REF!="", "", 'Data Input'!#REF!) -> #REF! | L5: =IF('Data Input'!#REF!="", "", 'Data Input'!#REF!) -> #REF!
A6: YEAR ENDING 31ST MARCH | B6: =IF('Data Input'!J11="", "", 'Data Input'!J11) -> 2024 | C6: =IF('Data Input'!K11="", "", 'Data Input'!K11) -> 2025 | D6: =IF('Data Input'!L11="", "", 'Data Input'!L11) -> 2026 | E6: =IF('Data Input'!#REF!="", "", 'Data Input'!#REF!) -> #REF! | F6: =IF('Data Input'!#REF!="", "", 'Data Input'!#REF!) -> #REF! | G6: =IF('Data Input'!#REF!="", "", 'Data Input'!#REF!) -> #REF! | H6: =IF('Data Input'!#REF!="", "", 'Data Input'!#REF!) -> #REF! | I6: =IF('Data Input'!#REF!="", "", 'Data Input'!#REF!) -> #REF! | J6: =IF('Data Input'!#REF!="", "", 'Data Input'!#REF!) -> #REF! | K6: =IF('Data Input'!#REF!="", "", 'Data Input'!#REF!) -> #REF! | L6: =IF('Data Input'!#REF!="", "", 'Data Input'!#REF!) -> #REF!
A7: NET PROFIT | B7: ='Data Input'!J57 -> 4.79 | C7: ='Data Input'!K57 -> 6.84 | D7: ='Data Input'!L57 -> 8.12 | E7: ='Data Input'!#REF! -> #REF! | F7: ='Data Input'!#REF! -> #REF! | G7: ='Data Input'!#REF! -> #REF! | H7: ='Data Input'!#REF! -> #REF! | I7: ='Data Input'!#REF! -> #REF! | J7: ='Data Input'!#REF! -> #REF! | K7: ='Data Input'!#REF! -> #REF! | L7: ='Data Input'!#REF! -> #REF!
A8: DEPRECIATION | B8: ='Data Input'!J29 -> 3.47 | C8: ='Data Input'!K29 -> 3.4 | D8: ='Data Input'!L29 -> 3.4 | E8: ='Data Input'!#REF! -> #REF! | F8: ='Data Input'!#REF! -> #REF! | G8: ='Data Input'!#REF! -> #REF! | H8: ='Data Input'!#REF! -> #REF! | I8: ='Data Input'!#REF! -> #REF! | J8: ='Data Input'!#REF! -> #REF! | K8: ='Data Input'!#REF! -> #REF! | L8: ='Data Input'!#REF! -> #REF!
A9: INTEREST ON LONG TERM LOANS | B9: ='Data Input'!J47 -> 0.6 | C9: ='Data Input'!K47 -> 0.21 | D9: ='Data Input'!L47 -> 0.12 | E9: ='Data Input'!#REF! -> #REF! | F9: ='Data Input'!#REF! -> #REF! | G9: ='Data Input'!#REF! -> #REF! | H9: ='Data Input'!#REF! -> #REF! | I9: ='Data Input'!#REF! -> #REF! | J9: ='Data Input'!#REF! -> #REF! | K9: ='Data Input'!#REF! -> #REF! | L9: ='Data Input'!#REF! -> #REF!
A10: OTHER NON CASH EXPENDITURE | B10: ='Data Input'!J56 -> 0 | C10: ='Data Input'!K56 -> 0 | D10: ='Data Input'!L56 -> 0 | E10: ='Data Input'!#REF! -> #REF! | F10: ='Data Input'!#REF! -> #REF! | G10: ='Data Input'!#REF! -> #REF! | H10: ='Data Input'!#REF! -> #REF! | I10: ='Data Input'!#REF! -> #REF! | J10: ='Data Input'!#REF! -> #REF! | K10: ='Data Input'!#REF! -> #REF! | L10: ='Data Input'!#REF! -> #REF!
A11: TOTAL (A) | B11: =SUM(B7:B10) -> 8.86 | C11: =SUM(C7:C10) -> 10.45 | D11: =SUM(D7:D10) -> 11.64 | E11: =SUM(E7:E10) -> #REF! | F11: =SUM(F7:F10) -> #REF! | G11: =SUM(G7:G10) -> #REF! | H11: =SUM(H7:H10) -> #REF! | I11: =SUM(I7:I10) -> #REF! | ... L11: =SUM(L7:L10) -> #REF!
A12: INTEREST ON LONG TERM LOANS | B12: ='Data Input'!J47 -> 0.6 | C12: ='Data Input'!K47 -> 0.21 | D12: ='Data Input'!L47 -> 0.12 | E12: ='Data Input'!#REF! -> #REF! | F12: ='Data Input'!#REF! -> #REF! | G12: ='Data Input'!#REF! -> #REF! | H12: ='Data Input'!#REF! -> #REF! | I12: ='Data Input'!#REF! -> #REF! | J12: ='Data Input'!#REF! -> #REF! | K12: ='Data Input'!#REF! -> #REF! | L12: ='Data Input'!#REF! -> #REF!
A13: PRINCIPLE PAYMENT OF TERM LOAN | B13: ='Data Input'!I79 -> 2.42 | C13: ='Data Input'!J79 -> 2.39 | D13: ='Data Input'!K79 -> 1.02 | E13: ='Data Input'!L79 -> 1.02 | F13: ='Data Input'!#REF! -> #REF! | G13: ='Data Input'!#REF! -> #REF! | H13: ='Data Input'!#REF! -> #REF! | I13: ='Data Input'!#REF! -> #REF! | J13: ='Data Input'!#REF! -> #REF! | K13: ='Data Input'!#REF! -> #REF! | L13: ='Data Input'!#REF! -> #REF!
A14: TOTAL (B) | B14: =SUM(B12:B13) -> 3.02 | C14: =SUM(C12:C13) -> 2.6 | D14: =SUM(D12:D13) -> 1.14 | E14: =SUM(E12:E13) -> #REF! | F14: =SUM(F12:F13) -> #REF! | G14: =SUM(G12:G13) -> #REF! | H14: =SUM(H12:H13) -> #REF! | I14: =SUM(I12:I13) -> #REF! | ... L14: =SUM(L12:L13) -> #REF!
A15: DSCR (A/B) | B15: =B11/B14 -> 2.9337748 | C15: =C11/C14 -> 4.0192308 | D15: =D11/D14 -> 10.210526 | E15: =E11/E14 -> #REF! | F15: =F11/F14 -> #REF! | G15: =G11/G14 -> #REF! | H15: =H11/H14 -> #REF! | I15: =I11/I14 -> #REF! | ... L15: =L11/L14 -> #REF!
A16: Average DSCR | B16: =SUM(B11:H11)/SUM(B14:H14) -> #REF!
B17: =B8+B7 -> 8.26 | C17: =C8+C7 -> 10.24 | D17: =D8+D7 -> 11.52 | E17: =E8+E7 -> #REF! | F17: =F8+F7 -> #REF! | G17: =G8+G7 -> #REF! | H17: =H8+H7 -> #REF! | I17: =I8+I7 -> #REF!
A18: IRR CALCULATION | B18: =+B5 -> Audited | C18: =+C5 -> Audited | D18: =+D5 -> Projected | E18: =+E5 -> Projected | F18: =+F5 -> #REF! | G18: =+G5 -> #REF! | H18: =+H5 -> #REF! | I18: =+I5 -> #REF! | ... L18: =+L5 -> #REF!
A19: YEAR ENDING 31ST MARCH | B19: =+B6 -> 2024 | C19: =+C6 -> 2025 | D19: =+D6 -> 2026 | E19: =+E6 -> #REF! | F19: =+F6 -> #REF! | G19: =+G6 -> #REF! | H19: =+H6 -> #REF! | I19: =+I6 -> #REF! | ... L19: =+L6 -> #REF!
A20: Year | B20: 0 | C20: 1 | D20: 2 | E20: 3 | F20: 4 | G20: 5 | H20: 6 | I20: 7 | J20: 8 | K20: 9 | L20: 10
A21: CAPEX Value | B21: =-'COP-MOF'!B16 -> #VALUE!
A22: Cash Accrual | B22: =B7+B8+B10 -> 8.26 | C22: =C7+C8+C10 -> 10.24 | D22: =D7+D8+D10 -> 11.52 | E22: =E7+E8+E10 -> #REF! | F22: =F7+F8+F10 -> #REF! | G22: =G7+G8+G10 -> #REF! | H22: =H7+H8+H10 -> #REF! | I22: =I7+I8+I10 -> #REF! | ... L22: =L7+L8+L10 -> #REF!
A23: Cash Flow | B23: =B21+B22 -> #VALUE! | C23: =C21+C22 -> 10.24 | D23: =D21+D22 -> 11.52 | E23: =E21+E22 -> #REF! | F23: =F21+F22 -> #REF! | G23: =G21+G22 -> #REF! | H23: =H21+H22 -> #REF! | I23: =I21+I22 -> #REF! | ... L23: =L21+L22 -> #REF! | M23: =IF(L23=0, IRR(B23:K23), IF(K23=0, IRR(B23:J23), IF(J23=0, IRR(B23:I23), IF(I23=0, IRR(B23:H23), IF(H23=0, IRR(B23:G23), IF(G23=0, IRR(B23:F23), IF(F23=0, IRR(B23:E23), IF(E23=0, IRR(B23:D23), IF(D23=0, IRR(B23:C23), IF(C23=0, IRR(B23), IRR(B23:L23))))))))))) -> #REF!
A24: IRR | B24: =+M23 -> #REF!

Sheet BEP
A1: =+'Data Input'!B5 -> Punjab National Bank
A2: =+'Data Input'!B6 -> MCC Durgapur
A3: =+'Data Input'!B7 -> Durgapur
A4: =+'Data Input'!B4 -> H R Ispat Pvt Ltd
B5: =IF('Data Input'!I10="", "", 'Data Input'!I10) -> Audited | C5: =IF('Data Input'!J10="", "", 'Data Input'!J10) -> Audited | D5: =IF('Data Input'!K10="", "", 'Data Input'!K10) -> Projected | E5: =IF('Data Input'!L10="", "", 'Data Input'!L10) -> Projected | F5: =IF('Data Input'!#REF!="", "", 'Data Input'!#REF!) -> #REF! | G5: =IF('Data Input'!#REF!="", "", 'Data Input'!#REF!) -> #REF! | H5: =IF('Data Input'!#REF!="", "", 'Data Input'!#REF!) -> #REF! | I5: =IF('Data Input'!#REF!="", "", 'Data Input'!#REF!) -> #REF! | J5: =IF('Data Input'!#REF!="", "", 'Data Input'!#REF!) -> #REF! | K5: =IF('Data Input'!#REF!="", "", 'Data Input'!#REF!) -> #REF! | L5: =IF('Data Input'!#REF!="", "", 'Data Input'!#REF!) -> #REF!
A6: YEAR ENDING 31ST MARCH | B6: =IF('Data Input'!I11="", "", 'Data Input'!I11) -> 2023 | C6: =IF('Data Input'!J11="", "", 'Data Input'!J11) -> 2024 | D6: =IF('Data Input'!K11="", "", 'Data Input'!K11) -> 2025 | E6: =IF('Data Input'!L11="", "", 'Data Input'!L11) -> 2026 | F6: =IF('Data Input'!#REF!="", "", 'Data Input'!#REF!) -> #REF! | G6: =IF('Data Input'!#REF!="", "", 'Data Input'!#REF!) -> #REF! | H6: =IF('Data Input'!#REF!="", "", 'Data Input'!#REF!) -> #REF! | I6: =IF('Data Input'!#REF!="", "", 'Data Input'!#REF!) -> #REF! | J6: =IF('Data Input'!#REF!="", "", 'Data Input'!#REF!) -> #REF! | K6: =IF('Data Input'!#REF!="", "", 'Data Input'!#REF!) -> #REF! | L6: =IF('Data Input'!#REF!="", "", 'Data Input'!#REF!) -> #REF!
A7: FIXED COST
A8: Depreciation | B8: ='Data Input'!I29 -> 3.23 | C8: ='Data Input'!J29 -> 3.47 | D8: ='Data Input'!K29 -> 3.4 | E8: ='Data Input'!L29 -> 3.4 | F8: ='Data Input'!#REF! -> #REF! | G8: ='Data Input'!#REF! -> #REF! | H8: ='Data Input'!#REF! -> #REF! | I8: ='Data Input'!#REF! -> #REF! | J8: ='Data Input'!#REF! -> #REF! | K8: ='Data Input'!#REF! -> #REF! | L8: ='Data Input'!#REF! -> #REF!
A9: =+'[2]TEV-Profitability Total'!A29:B29 -> Administrative & Selling Expenses | B9: ='Data Input'!I40 -> 1.92 | C9: ='Data Input'!J40 -> 3.6 | D9: ='Data Input'!K40 -> 3.17 | E9: ='Data Input'!L40 -> 3.62 | F9: ='Data Input'!#REF! -> #REF! | G9: ='Data Input'!#REF! -> #REF! | H9: ='Data Input'!#REF! -> #REF! | I9: ='Data Input'!#REF! -> #REF! | J9: ='Data Input'!#REF! -> #REF! | K9: ='Data Input'!#REF! -> #REF! | L9: ='Data Input'!#REF! -> #REF!
A10: Interest on Term Loan | B10: ='Data Input'!I47 -> 0.5 | C10: ='Data Input'!J47 -> 0.6 | D10: ='Data Input'!K47 -> 0.21 | E10: ='Data Input'!L47 -> 0.12 | F10: ='Data Input'!#REF! -> #REF! | G10: ='Data Input'!#REF! -> #REF! | H10: ='Data Input'!#REF! -> #REF! | I10: ='Data Input'!#REF! -> #REF! | J10: ='Data Input'!#REF! -> #REF! | K10: ='Data Input'!#REF! -> #REF! | L10: ='Data Input'!#REF! -> #REF!
A11: Cost of Production (Excl RM Cost & Depreciation) | B11: ='Data Input'!I35-'Data Input'!I29-'Data Input'!I21-'Data Input'!I24-'Data Input'!I25 -> 73.29 | C11: ='Data Input'!J35-'Data Input'!J29-'Data Input'!J21-'Data Input'!J24-'Data Input'!J25 -> 63.9 | D11: ='Data Input'!K35-'Data Input'!K29-'Data Input'!K21-'Data Input'!K24-'Data Input'!K25 -> 73.06 | E11: ='Data Input'!L35-'Data Input'!L29-'Data Input'!L21-'Data Input'!L24-'Data Input'!L25 -> 82.98 | F11: ='Data Input'!#REF!-'Data Input'!#REF!-'Data Input'!#REF!-'Data Input'!#REF!-'Data Input'!#REF! -> #REF! | G11: ='Data Input'!#REF!-'Data Input'!#REF!-'Data Input'!#REF!-'Data Input'!#REF!-'Data Input'!#REF! -> #REF! | H11: ='Data Input'!#REF!-'Data Input'!#REF!-'Data Input'!#REF!-'Data Input'!#REF!-'Data Input'!#REF! -> #REF! | I11: ='Data Input'!#REF!-'Data Input'!#REF!-'Data Input'!#REF!-'Data Input'!#REF!-'Data Input'!#REF! -> #REF! | J11: ='Data Input'!#REF!-'Data Input'!#REF!-'Data Input'!#REF!-'Data Input'!#REF!-'Data Input'!#REF! -> #REF! | K11: ='Data Input'!#REF!-'Data Input'!#REF!-'Data Input'!#REF!-'Data Input'!#REF!-'Data Input'!#REF! -> #REF! | L11: ='Data Input'!#REF!-'Data Input'!#REF!-'Data Input'!#REF!-'Data Input'!#REF!-'Data Input'!#REF! -> #REF!
A12: 30% of Cost of Prod. (Excl. RM Cost) | B12: =+B11*30% -> 21.987 | C12: =+C11*30% -> 19.17 | D12: =+D11*30% -> 21.918 | E12: =+E11*30% -> 24.894 | F12: =+F11*30% -> #REF! | G12: =+G11*30% -> #REF! | H12: =+H11*30% -> #REF! | I12: =+I11*30% -> #REF! | ... L12: =+L11*30% -> #REF!
A13: TOTAL FIXED COST (F) | B13: =SUM(B8:B10)+B12 -> 27.637 | C13: =SUM(C8:C10)+C12 -> 26.84 | D13: =SUM(D8:D10)+D12 -> 28.698 | E13: =SUM(E8:E10)+E12 -> 32.034 | F13: =SUM(F8:F10)+F12 -> #REF! | G13: =SUM(G8:G10)+G12 -> #REF! | H13: =SUM(H8:H10)+H12 -> #REF! | I13: =SUM(I8:I10)+I12 -> #REF! | ... L13: =SUM(L8:L10)+L12 -> #REF!
A14: PROFIT BEFOR TAX (P) | B14: ='Data Input'!I54 -> 10.58 | C14: ='Data Input'!J54 -> 7.01 | D14: ='Data Input'!K54 -> 9.66 | E14: ='Data Input'!L54 -> 12.1 | F14: ='Data Input'!#REF! -> #REF! | G14: ='Data Input'!#REF! -> #REF! | H14: ='Data Input'!#REF! -> #REF! | I14: ='Data Input'!#REF! -> #REF! | J14: ='Data Input'!#REF! -> #REF! | K14: ='Data Input'!#REF! -> #REF! | L14: ='Data Input'!#REF! -> #REF!
A15: BEP ON GIVEN SALES (= F/(F+P) ) | B15: =B13/(B13+B14) -> 0.72315985 | C15: =C13/(C13+C14) -> 0.7929099 | D15: =D13/(D13+D14) -> 0.74816205 | E15: =E13/(E13+E14) -> 0.72583496 | F15: =F13/(F13+F14) -> #REF! | G15: =G13/(G13+G14) -> #REF! | H15: =H13/(H13+H14) -> #REF! | I15: =I13/(I13+I14) -> #REF! | ... L15: =L13/(L13+L14) -> #REF!
A16: CASH BEP ON Given Gross Sales | B16: =(B13-B8)/(B13+B14) -> 0.63864249 | C16: =(C13-C8)/(C13+C14) -> 0.69039882 | D16: =(D13-D8)/(D13+D14) -> 0.65952344 | E16: =(E13-E8)/(E13+E14) -> 0.64879685 | F16: =(F13-F8)/(F13+F14) -> #REF! | G16: =(G13-G8)/(G13+G14) -> #REF! | H16: =(H13-H8)/(H13+H14) -> #REF! | I16: =(I13-I8)/(I13+I14) -> #REF! | ... L16: =(L13-L8)/(L13+L14) -> #REF!
A17: BEP IN TERMS OF SALES | B17: =B15*H18 -> 0 | C17: =C15*I18 -> 0 | D17: =D15*J18 -> 0 | E17: =E15*K18 -> 0 | F17: =F15*L18 -> #REF! | G17: =G15*M18 -> #REF! | H17: =H15*N18 -> #REF! | I17: =I15*O18 -> #REF! | ... L17: =L15*R18 -> #REF!
A18: CAPACITY UTILIZATION
A19: BEP ON UTILIZED CAPACITY | B19: =+B15*B18 -> 0 | C19: =+C15*C18 -> 0 | D19: =+D15*D18 -> 0 | E19: =+E15*E18 -> 0 | F19: =+F15*F18 -> #REF! | G19: =+G15*G18 -> #REF! | H19: =+H15*H18 -> #REF! | I19: =+I15*I18 -> #REF! | ... L19: =+L15*L18 -> #REF!
A20: CASH BEP ON UTILIZED CAPACITY | B20: =B18*B16 -> 0 | C20: =C18*C16 -> 0 | D20: =D18*D16 -> 0 | E20: =E18*E16 -> 0 | F20: =F18*F16 -> #REF! | G20: =G18*G16 -> #REF! | H20: =H18*H16 -> #REF! | I20: =I18*I16 -> #REF! | ... L20: =L18*L16 -> #REF!
A21: Break Even Point in Viability Year | E21: =+E15 -> 0.72583496
A22: Break Even Net Sales in Viability Year | E22: =+E17 -> 0

Sheet Sensitivity
B1: ='Data Input'!B5 -> Punjab National Bank
B2: ='Data Input'!B6 -> MCC Durgapur
B3: ='Data Input'!B7 -> Durgapur
B4: ='Data Input'!B4 -> H R Ispat Pvt Ltd
B5: CASE I | C5: =IF('Data Input'!I10="", "", 'Data Input'!I10) -> Audited | D5: =IF('Data Input'!J10="", "", 'Data Input'!J10) -> Audited | E5: =IF('Data Input'!K10="", "", 'Data Input'!K10) -> Projected | F5: =IF('Data Input'!L10="", "", 'Data Input'!L10) -> Projected | G5: =IF('Data Input'!#REF!="", "", 'Data Input'!#REF!) -> #REF! | H5: =IF('Data Input'!#REF!="", "", 'Data Input'!#REF!) -> #REF! | I5: =IF('Data Input'!#REF!="", "", 'Data Input'!#REF!) -> #REF! | J5: =IF('Data Input'!#REF!="", "", 'Data Input'!#REF!) -> #REF!
A6: Case I | B6: Raw Material Cost Up by 5% | C6: =IF('Data Input'!J11="", "", 'Data Input'!J11) -> 2024 | D6: =IF('Data Input'!K11="", "", 'Data Input'!K11) -> 2025 | E6: =IF('Data Input'!L11="", "", 'Data Input'!L11) -> 2026 | F6: =IF('Data Input'!#REF!="", "", 'Data Input'!#REF!) -> #REF! | G6: =IF('Data Input'!#REF!="", "", 'Data Input'!#REF!) -> #REF! | H6: =IF('Data Input'!#REF!="", "", 'Data Input'!#REF!) -> #REF! | I6: =IF('Data Input'!#REF!="", "", 'Data Input'!#REF!) -> #REF! | J6: =IF('Data Input'!#REF!="", "", 'Data Input'!#REF!) -> #REF!
A7: 1 | B7: Net Sales | C7: ='Data Input'!J18 -> 471.12 | D7: ='Data Input'!K18 -> 528.88 | E7: ='Data Input'!L18 -> 603.94 | F7: ='Data Input'!#REF! -> #REF! | G7: ='Data Input'!#REF! -> #REF! | H7: ='Data Input'!#REF! -> #REF! | I7: ='Data Input'!#REF! -> #REF! | J7: ='Data Input'!#REF! -> #REF!
